Workbook

Sheet заказ-order
I1: ,
B2: www.eclair.uz | C2: наш e-mail: info@eclair.uz | E2: info@eclair.uz | I2: ,
B3: Продукция / Products | C3: К-во шт.в ящ. / Quantity of pcs in a box | D3: Всего штук / Total pcs | E3: Количество в ящиках / Quantity of boxes | F3: Штрих коды Bar code | G3: Цена в $ США за шт. / Price in USD pcs. | I3: Код ТНВЭД
B4: Окрашивание волос | I4: ,
A5: № | B5: Стойкая крем-краска для волос «Éclair» с маслами «OMEGA 9», в саше пакетиках / Permanent hair color cream «Éclair» with «OMEGA-9» oils, sachet package | D5: =SUM(D6:D45) -> 0 | E5: =SUM(E6:E45) -> 0 | G5: 0.66 | H5: =G5*D5 -> 0 | I5: ,
A6: 1 | B6: Стойкая крем-краска для волос «Éclair» с маслами "OMEGA 9", тон 3.6 Баклажан / Aubergine | C6: 24 | D6: =+C6*E6 -> 0 | F6: 4780023323602 | I6: 3305900009
A7: 2 | B7: Стойкая крем-краска для волос «Éclair» с маслами "OMEGA 9", тон 4.6 Божоле / Dark Red | C7: 24 | D7: =+C7*E7 -> 0 | F7: 4780023323565 | I7: 3305900009
A8: 3 | B8: Стойкая крем-краска для волос «Éclair» с маслами "OMEGA 9", тон 5.5 Гранат / Deep Red | C8: 24 | D8: =+C8*E8 -> 0 | F8: 4780023323541 | I8: 3305900009
A9: 4 | B9: Стойкая крем-краска для волос «Éclair» с маслами "OMEGA 9", тон 4.5 Дикая вишня / Wild Cherry | C9: 24 | D9: =+C9*E9 -> 0 | F9: 4780023323572 | I9: 3305900009
A10: 5 | B10: Стойкая крем-краска для волос «Éclair» с маслами "OMEGA 9", тон 10.6 Жемчужно-серебристый / Pearl Silver Blonde | C10: 24 | D10: =+C10*E10 -> 0 | F10: 4780023323459 | I10: 3305900009
A11: 6 | B11: Стойкая крем-краска для волос «Éclair» с маслами "OMEGA 9", тон 1.1 Иссиня-черный / Bluish Black | C11: 24 | D11: =+C11*E11 -> 0 | F11: 4780023323626 | I11: 3305900009
A12: 7 | B12: Стойкая крем-краска для волос «Éclair» с маслами "OMEGA 9", тон 6.3 Капучино / Medium Dark Blonde | C12: 24 | D12: =+C12*E12 -> 0 | F12: 4780023323510 | I12: 3305900009
A13: 8 | B13: Стойкая крем-краска для волос «Éclair» с маслами "OMEGA 9", тон 9.7 Карамель / Caramel | C13: 24 | D13: =+C13*E13 -> 0 | F13: 4780023323466 | I13: 3305900009
A14: 9 | B14: Стойкая крем-краска для волос «Éclair» с маслами "OMEGA 9", тон 4.7 Каштан / Chesnut | C14: 24 | D14: =+C14*E14 -> 0 | F14: 4780023323589 | I14: 3305900009
A15: 10 | B15: Стойкая крем-краска для волос «Éclair» с маслами "OMEGA 9", тон 6.5 Махагон / Mahogany | C15: 24 | D15: =+C15*E15 -> 0 | F15: 4780023323534 | I15: 3305900009
A16: 11 | B16: Стойкая крем-краска для волос «Éclair» с маслоами "OMEGA 9", тон 6.7 Натуральный кофе / Coffe | C16: 24 | D16: =+C16*E16 -> 0 | F16: 4780023323497 | I16: 3305900009
A17: 12 | B17: Стойкая крем-краска для волос «Éclair» с маслами "OMEGA 9", тон 5.55 Рубин / Deep Mahogany | C17: 24 | D17: =+C17*E17 -> 0 | F17: 4780023323527 | I17: 3305900009
... A45: 40 | B45: Стойкая крем-краска для волос «Éclair» с маслами "OMEGA 9", тон 7.1 Холодный русый / Blond ash | C45: 24 | D45: =+C45*E45 -> 0 | F45: 4780023323084 | I45: 3305900009
I46: ,
A47: № | B47: Стойкая крем краска для волос «Éclair» «3D», в тубах по 50 мл / Permanent hair color cream «Éclair» «3D», in tubes | D47: =SUM(D48:D77) -> 0 | E47: =SUM(E48:E77) -> 0 | G47: 0.7 | H47: =G47*D47 -> 0 | I47: ,
A48: 1 | B48: Стойкая крем краска для волос «Éclair» «3D», тон 3.65 Баклажан / Aubergine | C48: 18 | D48: =E48*C48 -> 0 | F48: 4780023328249 | I48: 3305900009
A49: 2 | B49: Стойкая крем краска для волос «Éclair» «3D», тон 5.77 Шоколадный каштан / Chocolate brown | C49: 18 | D49: =E49*C49 -> 0 | F49: 4780023328256 | I49: 3305900009
A50: 3 | B50: Стойкая крем краска для волос «Éclair» «3D», тон 4.0 Роскошный каштан / Soft dark brown | C50: 18 | D50: =E50*C50 -> 0 | F50: 4780023328263 | I50: 3305900009
A51: 4 | B51: Стойкая крем краска для волос «Éclair» «3D», тон 5.0 Шоколадный / Chocolate | C51: 18 | D51: =E51*C51 -> 0 | F51: 4780023328270 | I51: 3305900009
A52: 5 | B52: Стойкая крем краска для волос «Éclair» «3D», тон 4.75 Черный шоколад / Black chocolate | C52: 18 | D52: =E52*C52 -> 0 | F52: 4780023328287 | I52: 3305900009
A53: 6 | B53: Стойкая крем краска для волос «Éclair» «3D», тон 7.0 Русый / Medium blonde | C53: 18 | D53: =E53*C53 -> 0 | F53: 4780023328294 | I53: 3305900009
A54: 7 | B54: Стойкая крем краска для волос «Éclair» «3D», тон 6.0 Темно- русый / Dark blonde | C54: 18 | D54: =E54*C54 -> 0 | F54: 4780023328300 | I54: 3305900009
A55: 8 | B55: Стойкая крем краска для волос «Éclair» «3D», тон 8.0 Светло-русый / Light blonde | C55: 18 | D55: =E55*C55 -> 0 | F55: 4780023328317 | I55: 3305900009
A56: 9 | B56: Стойкая крем краска для волос «Éclair» «3D», тон 4.56 Темная вишня / Dark cherry | C56: 18 | D56: =E56*C56 -> 0 | F56: 4780023328324 | I56: 3305900009
A57: 10 | B57: Стойкая крем краска для волос «Éclair» «3D», тон 2.81 Иссиня черный / Bluish black | C57: 18 | D57: =E57*C57 -> 0 | F57: 4780023328331 | I57: 3305900009
A58: 11 | B58: Стойкая крем краска для волос «Éclair» «3D», тон 7.1 Орехово-пепельный / Ash blonde | C58: 18 | D58: =E58*C58 -> 0 | F58: 4780023328348 | I58: 3305900009
A59: 12 | B59: Стойкая крем краска для волос «Éclair» «3D», тон 9.1 Жемчуг / Light ash blonde | C59: 18 | D59: =E59*C59 -> 0 | F59: 4780023328355 | I59: 3305900009
A60: 13 | B60: Стойкая крем краска для волос «Éclair» «3D», тон 10.20 Холодный блонд / Ultra Light ash blonde | C60: 18 | D60: =E60*C60 -> 0 | F60: 4780023328362 | I60: 3305900009
A61: 14 | B61: Стойкая крем краска для волос «Éclair» «3D», тон 11.13 Жемчужный блонд / Ice blonde | C61: 18 | D61: =E61*C61 -> 0 | F61: 4780023328379 | I61: 3305900009
... A77: 30 | B77: Стойкая крем краска для волос «Éclair» «3D», тон 10.31 Шампань / Naturlar light blonde | C77: 18 | D77: =E77*C77 -> 0 | F77: 4780023328539 | I77: 3305900009
I78: ,
A79: № | B79: Крем краска для бровей "ELETT" «Éclair» в тубах по 20мл / Eyebrow dye cream "ELETT" «Éclair» | D79: =SUM(D80:D81) -> 0 | E79: =SUM(E80:E81) -> 0 | G79: 0.81 | H79: =G79*D79 -> 0 | I79: ,
A80: 1 | B80: Крем краска для бровей "ELETT" тон 4.0 Коричневый / Brown | C80: 30 | D80: =+E80*C80 -> 0 | F80: 4780023326764 | I80: 3304200000
A81: 2 | B81: Крем краска для бровей "ELETT" тон 1.0 Черный /Black | C81: 30 | D81: =+E81*C81 -> 0 | F81: 4780023326757 | I81: 3304200000
I82: ,
...

Sheet логист.данные  logistic dim
A1: № з/п | B1: Код | C1: Продукция | D1: Ящики
D2: Ширина, м | E2: Длина, м | F2: Высота, м | G2: Объем, м. куб. | H2: Вес, кг брутто | I2: Вес, кг нетто | J2: К-во, ящ. | K2: ИТОГО Вес брутто кг | L2: ИТОГО Вес нетто кг | M2: ИТОГО Объем, м. куб.
A3: 1 | C3: Стойкая крем-краска для волос «Éclair» с маслами «OMEGA 9», в саше пакетиках / Permanent hair color cream «Éclair» with «OMEGA-9» oils, sachet package | D3: 0.29 | E3: 0.26 | F3: 0.174 | G3: =ROUND(D3*E3*F3,4) -> 0.0131 | H3: 3.68 | I3: 3.504 | J3: ='заказ-order'!E5 -> 0 | K3: =H3*J3 -> 0 | L3: =I3*J3 -> 0 | M3: =J3*D3*E3*F3 -> 0
A4: 3 | C4: Стойкая крем краска для волос «Éclair» «3D», в тубах по 50 мл / Permanent hair color cream «Éclair» «3D», in tubes 50 ml | D4: 0.29 | E4: 0.198 | F4: 0.173 | G4: =ROUND(D4*E4*F4,4) -> 0.0099 | H4: 2.58 | I4: 2.448 | J4: ='заказ-order'!E47 -> 0 | K4: =H4*J4 -> 0 | L4: =I4*J4 -> 0 | M4: =J4*D4*E4*F4 -> 0
A5: 4 | C5: Крем краска для бровей "ELETT" «Éclair» в тубах по 20мл / Eyebrow dye cream "ELETT" «Éclair» | D5: 0.238 | E5: 0.19 | F5: 0.13 | G5: =ROUND(D5*E5*F5,4) -> 0.0059 | H5: 1.8 | I5: 1.68 | J5: ='заказ-order'!E79 -> 0 | K5: =H5*J5 -> 0 | L5: =I5*J5 -> 0 | M5: =J5*D5*E5*F5 -> 0
A6: 5 | C6: Осветлитель для волос "Super Blond", в саше пакетиках / Hair bleaching "Super Blond", sachet package | D6: 0.415 | E6: 0.28 | F6: 0.18 | G6: =ROUND(D6*E6*F6,4) -> 0.0209 | H6: 3.48 | I6: 3.22 | J6: ='заказ-order'!E85 -> 0 | K6: =H6*J6 -> 0 | L6: =I6*J6 -> 0 | M6: =J6*D6*E6*F6 -> 0
A7: 6 | C7: Осветлитель для волосm"Ultra Blond" в саше пакетиках / Super Hair bleaching "Ultra Blond" , sachet package | D7: 0.33 | E7: 0.235 | F7: 0.18 | G7: =ROUND(D7*E7*F7,4) -> 0.014 | H7: 2.316 | I7: 2.12 | J7: ='заказ-order'!E86 -> 0 | K7: =H7*J7 -> 0 | L7: =I7*J7 -> 0 | M7: =J7*D7*E7*F7 -> 0
A8: 7 | C8: Окрашивающий шампунь "Coloring shampoo" «Éclair» для борьбы с сединой 25 мл / Coloring shampoo "Coloring shampoo" «Éclair» is a cpecial anti gray 25 ml | D8: 0.328 | E8: 0.194 | F8: 0.259 | G8: =ROUND(D8*E8*F8,4) -> 0.0165 | H8: 4.9 | I8: 4.68 | J8: ='заказ-order'!E89 -> 0 | K8: =H8*J8 -> 0 | L8: =I8*J8 -> 0 | M8: =J8*D8*E8*F8 -> 0
A9: 8 | C9: Восстанавливающий шампунь с Д - пантенолом 10 мл «Éclair» / Shampoo intensive hair restoration with D-panthenol | D9: 0.375 | E9: 0.495 | F9: 0.19 | G9: =ROUND(D9*E9*F9,4) -> 0.0353 | H9: 12.34 | I9: 11.6 | J9: ='заказ-order'!E93 -> 0 | K9: =H9*J9 -> 0 | L9: =I9*J9 -> 0 | M9: =J9*D9*E9*F9 -> 0
A10: 9 | C10: Шампунь для волос INTENSIVE «Éclair», 410 мл / Shampoo for hair INTENSIVE | D10: 0.262 | E10: 0.237 | F10: 0.22 | G10: =ROUND(D10*E10*F10,4) -> 0.0137 | H10: 8.16 | I10: 7.98 | J10: ='заказ-order'!E95 -> 0 | K10: =H10*J10 -> 0 | L10: =I10*J10 -> 0 | M10: =J10*D10*E10*F10 -> 0
A11: 10 | C11: Шампуни для волос "Infra Care" 900 мл / Shampoos for hair "Infra Care" 900 ml | D11: 0.33 | E11: 0.165 | F11: 0.255 | G11: =ROUND(D11*E11*F11,4) -> 0.0139 | H11: 8.02 | I11: 7.84 | J11: ='заказ-order'!E97 -> 0 | K11: =H11*J11 -> 0 | L11: =I11*J11 -> 0 | M11: =J11*D11*E11*F11 -> 0
A12: 11 | C12: Бальзам для волос "Infra Care" 900 мл / Hair balm "Infra Care" «Éclair» 900 ml | D12: 0.33 | E12: 0.165 | F12: 0.255 | G12: =ROUND(D12*E12*F12,4) -> 0.0139 | H12: 8 | I12: 7.82 | J12: ='заказ-order'!E104 -> 0 | K12: =H12*J12 -> 0 | L12: =I12*J12 -> 0 | M12: =J12*D12*E12*F12 -> 0
A13: 12 | C13: Шампуни для волос «Éclair» 830 мл / Shampoos for hair «Éclair» 830 ml | D13: 0.27 | E13: 0.195 | F13: 0.258 | G13: =ROUND(D13*E13*F13,4) -> 0.0136 | H13: 7.44 | I13: 7.28 | J13: =+'заказ-order'!E107 -> 0 | K13: =H13*J13 -> 0 | L13: =I13*J13 -> 0 | M13: =J13*D13*E13*F13 -> 0
A14: 13 | C14: Шампунь для волос SPUMA «Éclair» 400 мл / Shampoos for hair SPUMA | D14: 0.262 | E14: 0.237 | F14: 0.22 | G14: =ROUND(D14*E14*F14,4) -> 0.0137 | H14: 8.14 | I14: 7.96 | J14: ='заказ-order'!E112 -> 0 | K14: =H14*J14 -> 0 | L14: =I14*J14 -> 0 | M14: =J14*D14*E14*F14 -> 0
A15: 14 | C15: Бальзамов-ополаскиватель для волос SPUMA «Éclair», 240 мл / Hair balm-conditioner SPUMA «Éclair», 240 ml | D15: 0.3 | E15: 0.178 | F15: 0.191 | G15: =ROUND(D15*E15*F15,4) -> 0.0102 | H15: 5.58 | I15: 5.6 | J15: ='заказ-order'!E120 -> 0 | K15: =H15*J15 -> 0 | L15: =I15*J15 -> 0 | M15: =J15*D15*E15*F15 -> 0
A16: 15 | C16: Бальзамов-ополаскиватель для волос SPUMA «Éclair», 500 мл / Hair balm-conditioner SPUMA «Éclair», 500 ml | D16: 0.265 | E16: 0.265 | F16: 0.22 | G16: =ROUND(D16*E16*F16,4) -> 0.0154 | H16: 10.02 | I16: 9.82 | J16: ='заказ-order'!E126 -> 0 | K16: =H16*J16 -> 0 | L16: =I16*J16 -> 0 | M16: =J16*D16*E16*F16 -> 0
A17: 16 | C17: Шампунь для волос "ERSOLLE" «Éclair», 1000 мл / Hair shampoo | D17: 0.324 | E17: 0.164 | F17: 0.293 | G17: =ROUND(D17*E17*F17,4) -> 0.0156 | H17: 8.88 | I17: 8.68 | J17: ='заказ-order'!E134 -> 0 | K17: =H17*J17 -> 0 | L17: =I17*J17 -> 0 | M17: =J17*D17*E17*F17 -> 0
A18: 17 | C18: Бальзамов-ополаскиватель для волос "ERSOLLE" «Éclair», 500 мл / Hair balm-conditioner | D18: 0.275 | E18: 0.265 | F18: 0.225 | G18: =ROUND(D18*E18*F18,4) -> 0.0164 | H18: 9.96 | I18: 9.76 | J18: ='заказ-order'!E140 -> 0 | K18: =H18*J18 -> 0 | L18: =I18*J18 -> 0 | M18: =J18*D18*E18*F18 -> 0
A19: 18 | C19: Шампунь для волос "CAREAL" «Éclair» 1000мл / Shampoos for hair "CAREAL" «Éclair» | D19: 0.324 | E19: 0.164 | F19: 0.293 | G19: =ROUND(D19*E19*F19,4) -> 0.0156 | H19: 8.788 | I19: 9 | J19: ='заказ-order'!E146 -> 0 | K19: =H19*J19 -> 0 | L19: =I19*J19 -> 0 | M19: =J19*D19*E19*F19 -> 0
A20: 19 | C20: Шампунь для волос "BELANSA" «Éclair» 1100мл / Shampoos for hair "BELANSA" «Éclair» | D20: 0.272 | E20: 0.2 | F20: 0.313 | G20: =ROUND(D20*E20*F20,4) -> 0.017 | H20: 9.74 | I20: 9.504 | J20: ='заказ-order'!E151 -> 0 | K20: =H20*J20 -> 0 | L20: =I20*J20 -> 0 | M20: =J20*D20*E20*F20 -> 0
A21: 20 | C21: Шампунь для волос "HAIREC" «Éclair» 730мл / Shampoos for hair "HAIREC" «Éclair» | D21: 0.287 | E21: 0.19 | F21: 0.285 | G21: =ROUND(D21*E21*F21,4) -> 0.0155 | H21: 8.23 | I21: 8.074 | J21: ='заказ-order'!E157 -> 0 | K21: =H21*J21 -> 0 | L21: =I21*J21 -> 0 | M21: =J21*D21*E21*F21 -> 0
A22: 21 | C22: Шампунь для волос "REVITA" «Éclair» 730мл / Shampoos for hair "REVITA" «Éclair» | D22: 0.287 | E22: 0.19 | F22: 0.285 | G22: =ROUND(D22*E22*F22,4) -> 0.0155 | H22: 8.26 | I22: 8.06 | J22: ='заказ-order'!E163 -> 0 | K22: =H22*J22 -> 0 | L22: =I22*J22 -> 0 | M22: =J22*D22*E22*F22 -> 0
A23: 22 | C23: Бальзам для волос "REVITA" «Éclair» 710мл / Balm hair "REVITA" «Éclair» | D23: 0.287 | E23: 0.19 | F23: 0.285 | G23: =ROUND(D23*E23*F23,4) -> 0.0155 | H23: 8.08 | I23: 7.88 | J23: ='заказ-order'!E169 -> 0 | K23: =H23*J23 -> 0 | L23: =I23*J23 -> 0 | M23: =J23*D23*E23*F23 -> 0
A24: 23 | C24: Гель для душа "REVITA" «Éclair» 730мл / Shower gel "REVITA" «Éclair» | D24: 0.287 | E24: 0.19 | F24: 0.285 | G24: =ROUND(D24*E24*F24,4) -> 0.0155 | H24: 8.26 | I24: 8.06 | J24: ='заказ-order'!E175 -> 0 | K24: =H24*J24 -> 0 | L24: =I24*J24 -> 0 | M24: =J24*D24*E24*F24 -> 0
A25: 24 | C25: Шампунь для волос "BRIO" для мужчин «Éclair» 730мл / Shampoos for hair "BRIO" for men «Éclair» | D25: 0.287 | E25: 0.19 | F25: 0.285 | G25: =ROUND(D25*E25*F25,4) -> 0.0155 | H25: 8.24 | I25: 8.06 | J25: ='заказ-order'!E181 -> 0 | K25: =H25*J25 -> 0 | L25: =I25*J25 -> 0 | M25: =J25*D25*E25*F25 -> 0
A26: 25 | C26: Гель для душа "BRIO" для мужчин «Éclair» 730мл / Shower gel "BRIO" for men «Éclair» | D26: 0.287 | E26: 0.19 | F26: 0.285 | G26: =ROUND(D26*E26*F26,4) -> 0.0155 | H26: 8.28 | I26: 8.08 | J26: ='заказ-order'!E186 -> 0 | K26: =H26*J26 -> 0 | L26: =I26*J26 -> 0 | M26: =J26*D26*E26*F26 -> 0
A27: 26 | C27: Крем для бритья BRIO «Éclair» в тубах по 75 мл / Shaving cream BRIO «Éclair» 75 mlin tubes | D27: 0.24 | E27: 0.17 | F27: 0.17 | G27: =ROUND(D27*E27*F27,4) -> 0.0069 | H27: 2.334 | I27: 2.208 | J27: ='заказ-order'!E191 -> 0 | K27: =H27*J27 -> 0 | L27: =I27*J27 -> 0 | M27: =J27*D27*E27*F27 -> 0
A28: 27 | C28: Крем после бритья BRIO «Éclair» в тубах по 50 мл / After shave cream BRIO «Éclair» 50 ml in tubes | D28: 0.25 | E28: 0.19 | F28: 0.135 | G28: =ROUND(D28*E28*F28,4) -> 0.0064 | H28: 1.676 | I28: 1.536 | J28: ='заказ-order'!E196 -> 0 | K28: =H28*J28 -> 0 | L28: =I28*J28 -> 0 | M28: =J28*D28*E28*F28 -> 0
A29: 28 | C29: Детский шампунь "HANY" «Éclair Kids» 240мл / Baby shampoo "HANY" «Éclair Kids» | D29: 0.31 | E29: 0.178 | F29: 0.193 | G29: =ROUND(D29*E29*F29,4) -> 0.0106 | H29: 5.62 | I29: 5.44 | J29: ='заказ-order'!E201 -> 0 | K29: =H29*J29 -> 0 | L29: =I29*J29 -> 0 | M29: =J29*D29*E29*F29 -> 0
A30: 29 | C30: Детский шампунь "UPPY" «Éclair» без сульфатов и краситилей 250 мл / Baby shampoo "UPPY" «Éclair» without sulfates and dyes 250 ml | D30: 0.265 | E30: 0.225 | F30: 0.18 | G30: =ROUND(D30*E30*F30,4) -> 0.0107 | H30: 5.123 | I30: 4.932 | J30: ='заказ-order'!E206 -> 0 | K30: =H30*J30 -> 0 | L30: =I30*J30 -> 0 | M30: =J30*D30*E30*F30 -> 0
A31: 30 | C31: Детское масло "UPPY" «Éclair» для чуствительной кожи 160 мл / Baby oil "UPPY"«Éclair» for sensitive skin 160 ml | D31: 0.29 | E31: 0.18 | F31: 0.17 | G31: =ROUND(D31*E31*F31,4) -> 0.0089 | H31: 3.78 | I31: 3.64 | J31: ='заказ-order'!E207 -> 0 | K31: =H31*J31 -> 0 | L31: =I31*J31 -> 0 | M31: =J31*D31*E31*F31 -> 0
A32: 31 | C32: Детский крем "UPPY" «Éclair» гипоаллергеенный 60 мл / Baby cream "UPPY" «Éclair» hypoallergenic 60 ml | D32: 0.255 | E32: 0.185 | F32: 0.135 | G32: =ROUND(D32*E32*F32,4) -> 0.0064 | H32: 2.48 | I32: 2.359 | J32: ='заказ-order'!E208 -> 0 | K32: =H32*J32 -> 0 | L32: =I32*J32 -> 0 | M32: =J32*D32*E32*F32 -> 0
A33: 32 | C33: Детская пресипка "UPPY" «Éclair» сохряняет сухост кожи 100 мл / Baby powder "UPPY" "Éclair" keeps the skin dry 100 ml | D33: 0.265 | E33: 0.207 | F33: 0.135 | G33: =ROUND(D33*E33*F33,4) -> 0.0074 | H33: 3.04 | I33: 2.904 | J33: ='заказ-order'!E209 -> 0 | K33: =H33*J33 -> 0 | L33: =I33*J33 -> 0 | M33: =J33*D33*E33*F33 -> 0
A34: 33 | C34: Десткое туалетное мыло "UPPY" «Éclair» не раздражает кожу 90 гр / Baby soap "UPPY" "Éclair" does not irritate the skin 90 gr | D34: 0.258 | E34: 0.17 | F34: 0.188 | G34: =ROUND(D34*E34*F34,4) -> 0.0082 | H34: 4.56 | I34: 4.44 | J34: ='заказ-order'!E210 -> 0 | K34: =H34*J34 -> 0 | L34: =I34*J34 -> 0 | M34: =J34*D34*E34*F34 -> 0
A35: 34 | C35: Шампун для волос "Amfiora" «Éclair» 830 мл / Shampoo for hair 830 ml | D35: 0.27 | E35: 0.195 | F35: 0.258 | G35: =ROUND(D35*E35*F35,4) -> 0.0136 | H35: 8.8 | I35: 8.6 | J35: ='заказ-order'!E213 -> 0 | K35: =H35*J35 -> 0 | L35: =I35*J35 -> 0 | M35: =J35*D35*E35*F35 -> 0
A36: 35 | C36: Бальзам для волос "Amfiora" «Éclair» 500 мл / Hair balm 500 ml | D36: 0.315 | E36: 0.31 | F36: 0.18 | G36: =ROUND(D36*E36*F36,4) -> 0.0176 | H36: 10.1 | I36: 9.84 | J36: ='заказ-order'!E214 -> 0 | K36: =H36*J36 -> 0 | L36: =I36*J36 -> 0 | M36: =J36*D36*E36*F36 -> 0
A37: 36 | C37: Пенка для умывания лица "Amfiora" «Éclair» , в тубах по 180 мл / Face foam cleancer 180 ml in tubes | D37: 0.3 | E37: 0.158 | F37: 0.168 | G37: =ROUND(D37*E37*F37,4) -> 0.008 | H37: 3.7 | I37: 3.58 | J37: ='заказ-order'!E215 -> 0 | K37: =H37*J37 -> 0 | L37: =I37*J37 -> 0 | M37: =J37*D37*E37*F37 -> 0
A38: 37 | C38: Скраб для лица "Amfiora" «Éclair» , в тубах по 150 мл / Face scrub 150 ml in tubes | D38: 0.3 | E38: 0.158 | F38: 0.168 | G38: =ROUND(D38*E38*F38,4) -> 0.008 | H38: 3.18 | I38: 3.04 | J38: ='заказ-order'!E216 -> 0 | K38: =H38*J38 -> 0 | L38: =I38*J38 -> 0 | M38: =J38*D38*E38*F38 -> 0
A39: 38 | C39: Крем для депиляции "Amfiora" «Éclair» в тубах по 100 мл / Depilatory cream 100 ml in tubes | D39: 0.316 | E39: 0.19 | F39: 0.177 | G39: =ROUND(D39*E39*F39,4) -> 0.0106 | H39: 2.72 | I39: 2.56 | J39: ='заказ-order'!E217 -> 0 | K39: =H39*J39 -> 0 | L39: =I39*J39 -> 0 | M39: =J39*D39*E39*F39 -> 0
A40: 39 | C40: Крем для лица "Amfiora" «Éclair» в баночках по 150 мл / Face cream 150 ml in jars | D40: 0.285 | E40: 0.215 | F40: 0.18 | G40: =ROUND(D40*E40*F40,4) -> 0.011 | H40: 6.62 | I40: 6.4 | J40: ='заказ-order'!E218 -> 0 | K40: =H40*J40 -> 0 | L40: =I40*J40 -> 0 | M40: =J40*D40*E40*F40 -> 0
...

Sheet логист.данные  logistic dimenst
A1: № з/п | B1: Код | C1: Продукция | D1: Ящики
D2: Ширина, м | E2: Длина, м | F2: Высота, м | G2: Объем, м. куб. | H2: Вес, кг брутто | I2: К-во, ящ. | J2: ИТОГО Вес брутто кг | K2: ИТОГО Вес нетто кг | L2: ИТОГО Объем, м. куб.
A3: 1 | C3: =+'заказ-order'!#REF! -> #REF! | D3: 0.37 | E3: 0.205 | F3: 0.18 | G3: =ROUND(D3*E3*F3,4) -> 0.0137 | H3: 3.4 | I3: ='заказ-order'!#REF! -> #REF! | J3: =H3*I3 -> #REF! | L3: =I3*D3*E3*F3 -> #REF!
A4: =+A3+1 -> 2 | C4: =+'заказ-order'!B47 -> Стойкая крем краска для волос «Éclair» «3D», в тубах по 50 мл / Permanent hair color cream «Éclair» «3D», in tubes | D4: 0.24 | E4: 0.295 | F4: 0.185 | G4: =ROUND(D4*E4*F4,4) -> 0.0131 | H4: 3.101 | I4: =+'заказ-order'!E47 -> 0 | J4: =H4*I4 -> 0 | L4: =I4*D4*E4*F4 -> 0
A5: =+A4+1 -> 3 | C5: =+'заказ-order'!#REF! -> #REF! | D5: 0.24 | E5: 0.295 | F5: 0.185 | G5: =ROUND(D5*E5*F5,4) -> 0.0131 | H5: 3.766 | I5: =+'заказ-order'!#REF! -> #REF! | J5: =H5*I5 -> #REF! | L5: =I5*D5*E5*F5 -> #REF!
A6: =+A5+1 -> 4 | C6: =+'заказ-order'!B5 -> Стойкая крем-краска для волос «Éclair» с маслами «OMEGA 9», в саше пакетиках / Permanent hair color cream «Éclair» with «OMEGA-9» oils, sachet package
A7: =+A6+1 -> 5 | C7: =+'заказ-order'!B256 -> Кремы «Éclair», в тубах по 44 мл / Сreams «Éclair» in tubes
A8: =+A7+1 -> 6 | C8: =+'заказ-order'!#REF! -> #REF!
A9: =+A8+1 -> 7 | C9: =+'заказ-order'!B140 -> Бальзамов-ополаскиватель для волос "ERSOLLE" «Éclair», 500 мл / Hair balm-conditioner
A10: =+A9+1 -> 8 | C10: =+'заказ-order'!#REF! -> #REF!
A11: =+A10+1 -> 9 | C11: =+'заказ-order'!#REF! -> #REF!
A12: =+A11+1 -> 10 | C12: =+'заказ-order'!#REF! -> #REF!
A13: =+A12+1 -> 11 | C13: =+'заказ-order'!B244 -> Мицеллярная вода "ELETT" «Éclair», 200 мл / Micellar water "ELETT" «Éclair», 200 ml.
A14: =+A13+1 -> 12 | C14: =+'заказ-order'!#REF! -> #REF!
A15: =+A14+1 -> 13 | C15: =+'заказ-order'!B79 -> Крем краска для бровей "ELETT" «Éclair» в тубах по 20мл / Eyebrow dye cream "ELETT" «Éclair»
A16: =+A15+1 -> 14 | C16: =+'заказ-order'!#REF! -> #REF!
A17: =+A16+1 -> 15 | C17: =+'заказ-order'!#REF! -> #REF!
A18: =+A17+1 -> 16 | C18: =+'заказ-order'!#REF! -> #REF!
A19: =+A18+1 -> 17 | C19: =+'заказ-order'!#REF! -> #REF!
A20: =+A19+1 -> 18 | C20: =+'заказ-order'!B89 -> Окрашивающий шампунь "Coloring shampoo" «Éclair» для борьбы с сединой 25 мл / Coloring shampoo "Coloring shampoo" «Éclair» is a cpecial anti gray 25 ml | M20: =+H20/30*100 -> 0
A21: =+A20+1 -> 19 | C21: =+'заказ-order'!B213 -> Шампун для волос 830 мл / Shampoo for hair 830 ml
A22: =+A21+1 -> 20 | C22: =+'заказ-order'!B214 -> Бальзам для волос 500 мл / Hair balm 500 ml
A23: =+A22+1 -> 21 | C23: =+'заказ-order'!B216 -> Скраб для лица, в тубах по 150 мл / Face scrub 150 ml in tubes
A24: =+A23+1 -> 22 | C24: =+'заказ-order'!B217 -> Крем для депиляции в тубах по 100 мл / Depilatory cream 100 ml in tubes
A25: =+A24+1 -> 23 | C25: =+'заказ-order'!B218 -> Крем для лица в баночках по 150 мл / Face cream 150 ml in jars
A26: =+A25+1 -> 24 | C26: =+'заказ-order'!B219 -> Крем для рук в баночках по 150 мл / Hand cream 150 ml in jars
A27: =+A26+1 -> 25 | C27: =+'заказ-order'!B220 -> Крем для ног в баночках 75 мл / Foot cream 75 ml in jars
A28: =+A27+1 -> 26 | C28: =+'заказ-order'!B95 -> Шампунь для волос INTENSIVE «Éclair», 410 мл / Shampoo for hair
A29: =+A28+1 -> 27 | C29: =+'заказ-order'!#REF! -> #REF!
A30: =+A29+1 -> 28 | C30: =+'заказ-order'!B201 -> Детский шампунь "HANY" «Éclair Kids» 240мл / Baby shampoo "HANY" «Éclair Kids»
A31: =+A30+1 -> 29 | C31: =+'заказ-order'!B203 -> Детскый шампунь без алергенный с экстрактом ромашки / Allergenic-free baby shampoo with chamomile extract
A32: =+A31+1 -> 30 | C32: =+'заказ-order'!#REF! -> #REF!
A33: =+A32+1 -> 31 | C33: =+'заказ-order'!#REF! -> #REF!
A34: =+A33+1 -> 32 | C34: =+'заказ-order'!#REF! -> #REF!
A35: =+A34+1 -> 33 | C35: =+'заказ-order'!B85 -> Осветлитель для волос "Super Blond", в саше пакетиках / Hair bleaching "Super Blond", sachet package
A36: =+A35+1 -> 34 | C36: =+'заказ-order'!B86 -> Осветлитель для волосm"Ultra Blond" в саше пакетиках / Super Hair bleaching "Ultra Blond" , sachet package
A37: =+A36+1 -> 35 | C37: =+'заказ-order'!#REF! -> #REF! | M37: =+H37/8 -> 0
A38: =+A37+1 -> 36 | C38: =+'заказ-order'!#REF! -> #REF!
A39: =+A38+1 -> 37 | C39: =+'заказ-order'!#REF! -> #REF!
A40: =+A39+1 -> 38 | C40: =+'заказ-order'!#REF! -> #REF!
...
